Workbook

Sheet МТР
A1: № КС | B1: Шифр сметы | C1: 1 - Труд 2 - ЭММ 3 - МАТ | D1: Column5 | E1: Обоснование | F1: Наименование | G1: Ед. изм. | H1: Расход | I1: Базовая цена | J1: Стоимость | K1: =1-SUMIFS(K2:K1590,O2:O1590,"") -> 0.88237884 | L1: #1 | M1: #2 | N1: #3 | O1: Средняя цена, EGP, без НДС | P1: Наименование 1 | Q1: ЕдИзм1 | R1: Цена1 на площадке, EGP без НДС | S1: ДатаЦены1 | T1: Поставщик1 | U1: Обоснование1 | V1: Наименование 2 | W1: ЕдИзм2 | X1: Цена2 на площадке, EGP без НДС | Y1: ДатаЦены2 | Z1: Поставщик2 | AA1: Обоснование2 | AB1: Наименование 3 | AC1: ЕдИзм3 | AD1: Цена3 на площадке, EGP без НДС | AE1: ДатаЦены3 | AF1: Поставщик3 | AG1: Обоснование3 | AH1: ID1 | AI1: ID2 | AJ1: ID3
A2: 2 | B2: ЛСР-03-08-201ТМ | C2: 3 | E2: ТЦ_23.7.01.02_31_3123315768_20.05.2022_02/ КА п.1/ ООО "Белэнергомаш-БЗЭМ" №006-00073 | F2: Трубопроводы низкого давления из нержавеющей стали 4 класса безопасности Ду > 80мм_ DN 900 | G2: т | H2: 44.174 | I2: 799960.85 | J2: =H2*I2 -> 35337471 | K2: =J2/SUM($J$2:$J$1590) -> 0.27672821 | L2: =IFERROR(INDEX([1]мтр!G:G,MATCH($F2,[1]мтр!$C:$C,0)),"") -> 4861 | M2: =IFERROR(INDEX([1]мтр!H:H,MATCH($F2,[1]мтр!$C:$C,0)),"") -> 0 | N2: =IFERROR(INDEX([1]мтр!I:I,MATCH($F2,[1]мтр!$C:$C,0)),"") -> 0 | O2: =IFERROR(AVERAGE(R2,X2,AD2),"") -> 2050605.2 | P2: =IFERROR(INDEX([2]Лист1!$E:$E,AH2),"") -> Трубопроводы низкого давления из нержавеющей стали зданий UJA, UKD. Объём: 40 315 616 руб. / 6 074,16 кг = 6637 RUB/кг. Транспорт 5800 USD (Договор ЕОС-закупки №629007, №7720/220816 от 07.09.2022, АСЭ_Рускон) /40DV контейнер 25 т, класс груза - 2, загрузка 85%. | Q2: =IFERROR(INDEX([2]Лист1!$I:$I,AH2),"") -> т | R2: =IFERROR(INDEX([2]Лист1!$V:$V,AH2),"") -> 2050605.2 | S2: =IFERROR(INDEX([2]Лист1!$L:$L,AH2),"") -> 44753 | T2: =IFERROR(INDEX([2]Лист1!$J:$J,AH2),"") -> Белэнергомаш-БЗЭМ | U2: =IFERROR(INDEX([2]Лист1!$K:$K,AH2),"") -> Поставка трубопроводов по лоту 19677-248 Куд3;4. НМЦ от 11.07.2022, рассчитанная на основании п.1 раздела 3 главы 3 (приложения №8 к ЕОСЗ). | V2: =IFERROR(INDEX([2]Лист1!$E:$E,AI2),"") | W2: =IFERROR(INDEX([2]Лист1!$I:$I,AI2),"") | X2: =IFERROR(INDEX([2]Лист1!$V:$V,AI2),"") | Y2: =IFERROR(INDEX([2]Лист1!$L:$L,AI2),"") | Z2: =IFERROR(INDEX([2]Лист1!$J:$J,AI2),"") | AA2: =IFERROR(INDEX([2]Лист1!$K:$K,AI2),"") | AB2: =IFERROR(INDEX([2]Лист1!$E:$E,AJ2),"") | AC2: =IFERROR(INDEX([2]Лист1!$I:$I,AJ2),"") | AD2: =IFERROR(INDEX([2]Лист1!$V:$V,AJ2),"") | AE2: =IFERROR(INDEX([2]Лист1!$L:$L,AJ2),"") | AF2: =IFERROR(INDEX([2]Лист1!$J:$J,AJ2),"") | AG2: =IFERROR(INDEX([2]Лист1!$K:$K,AJ2),"") | AH2: =MATCH(L2,[2]Лист1!$A:$A,0) -> 4798 | AI2: =MATCH(M2,[2]Лист1!$A:$A,0) -> #N/A | AJ2: =MATCH(N2,[2]Лист1!$A:$A,0) -> #N/A
A3: 1 | B3: ЛСР-03-05-602Э | C3: 3 | E3: ТЦ_20.2.07.00_31.03.2022_01/КА табл.1, п.2/WIBE Group в России/ED.B.P000.&.1104&&&&&&&&.031.TD.0001 | F3: Конструкции кабельные разных размеров, включая стойки, полки, лотки, короба | G3: кг | H3: 27000 | I3: 398.56 | J3: =H3*I3 -> 10761120 | K3: =J3/SUM($J$2:$J$1590) -> 0.084270475 | L3: =IFERROR(INDEX([1]мтр!G:G,MATCH($F3,[1]мтр!$C:$C,0)),"") -> 3411 | M3: =IFERROR(INDEX([1]мтр!H:H,MATCH($F3,[1]мтр!$C:$C,0)),"") -> 0 | N3: =IFERROR(INDEX([1]мтр!I:I,MATCH($F3,[1]мтр!$C:$C,0)),"") -> 0 | O3: =IFERROR(AVERAGE(R3,X3,AD3),"") -> 448.64572 | P3: =IFERROR(INDEX([2]Лист1!$E:$E,AH3),"") -> Конструкции кабельные разных размеров (стойки, полки, лотки, короб и т.д.) из горячеоцинкованной стали на основе спецификаций материалов проекта ЛАЭС-2.Транспорт экспертно 5% | Q3: =IFERROR(INDEX([2]Лист1!$I:$I,AH3),"") -> кг | R3: =IFERROR(INDEX([2]Лист1!$V:$V,AH3),"") -> 448.64572 | S3: =IFERROR(INDEX([2]Лист1!$L:$L,AH3),"") -> 44344 | T3: =IFERROR(INDEX([2]Лист1!$J:$J,AH3),"") -> Schneider Electric | U3: =IFERROR(INDEX([2]Лист1!$K:$K,AH3),"") -> Письмо от 28.05.2021 | V3: =IFERROR(INDEX([2]Лист1!$E:$E,AI3),"") | W3: =IFERROR(INDEX([2]Лист1!$I:$I,AI3),"") | X3: =IFERROR(INDEX([2]Лист1!$V:$V,AI3),"") | Y3: =IFERROR(INDEX([2]Лист1!$L:$L,AI3),"") | Z3: =IFERROR(INDEX([2]Лист1!$J:$J,AI3),"") | AA3: =IFERROR(INDEX([2]Лист1!$K:$K,AI3),"") | AB3: =IFERROR(INDEX([2]Лист1!$E:$E,AJ3),"") | AC3: =IFERROR(INDEX([2]Лист1!$I:$I,AJ3),"") | AD3: =IFERROR(INDEX([2]Лист1!$V:$V,AJ3),"") | AE3: =IFERROR(INDEX([2]Лист1!$L:$L,AJ3),"") | AF3: =IFERROR(INDEX([2]Лист1!$J:$J,AJ3),"") | AG3: =IFERROR(INDEX([2]Лист1!$K:$K,AJ3),"") | AH3: =MATCH(L3,[2]Лист1!$A:$A,0) -> 2824 | AI3: =MATCH(M3,[2]Лист1!$A:$A,0) -> #N/A | AJ3: =MATCH(N3,[2]Лист1!$A:$A,0) -> #N/A
A4: 1 | B4: ЛСР-03-05-206ТМ | C4: 3 | E4: ТЦ_23.7.01.02_31_3123315768_20.05.2022_02/ КА п.78/ ООО "Белэнергомаш-БЗЭМ" №006-00073 | F4: Трубопроводы низкого давления из нержавеющей стали 4 класса безопасности Ду > 80мм_ DN 900 | G4: т | H4: 4.554 | I4: 799960.85 | J4: =H4*I4 -> 3643021.7 | K4: =J4/SUM($J$2:$J$1590) -> 0.028528552 | L4: =IFERROR(INDEX([1]мтр!G:G,MATCH($F4,[1]мтр!$C:$C,0)),"") -> 4861 | M4: =IFERROR(INDEX([1]мтр!H:H,MATCH($F4,[1]мтр!$C:$C,0)),"") -> 0 | N4: =IFERROR(INDEX([1]мтр!I:I,MATCH($F4,[1]мтр!$C:$C,0)),"") -> 0 | O4: =IFERROR(AVERAGE(R4,X4,AD4),"") -> 2050605.2 | P4: =IFERROR(INDEX([2]Лист1!$E:$E,AH4),"") -> Трубопроводы низкого давления из нержавеющей стали зданий UJA, UKD. Объём: 40 315 616 руб. / 6 074,16 кг = 6637 RUB/кг. Транспорт 5800 USD (Договор ЕОС-закупки №629007, №7720/220816 от 07.09.2022, АСЭ_Рускон) /40DV контейнер 25 т, класс груза - 2, загрузка 85%. | Q4: =IFERROR(INDEX([2]Лист1!$I:$I,AH4),"") -> т | R4: =IFERROR(INDEX([2]Лист1!$V:$V,AH4),"") -> 2050605.2 | S4: =IFERROR(INDEX([2]Лист1!$L:$L,AH4),"") -> 44753 | T4: =IFERROR(INDEX([2]Лист1!$J:$J,AH4),"") -> Белэнергомаш-БЗЭМ | U4: =IFERROR(INDEX([2]Лист1!$K:$K,AH4),"") -> Поставка трубопроводов по лоту 19677-248 Куд3;4. НМЦ от 11.07.2022, рассчитанная на основании п.1 раздела 3 главы 3 (приложения №8 к ЕОСЗ). | V4: =IFERROR(INDEX([2]Лист1!$E:$E,AI4),"") | W4: =IFERROR(INDEX([2]Лист1!$I:$I,AI4),"") | X4: =IFERROR(INDEX([2]Лист1!$V:$V,AI4),"") | Y4: =IFERROR(INDEX([2]Лист1!$L:$L,AI4),"") | Z4: =IFERROR(INDEX([2]Лист1!$J:$J,AI4),"") | AA4: =IFERROR(INDEX([2]Лист1!$K:$K,AI4),"") | AB4: =IFERROR(INDEX([2]Лист1!$E:$E,AJ4),"") | AC4: =IFERROR(INDEX([2]Лист1!$I:$I,AJ4),"") | AD4: =IFERROR(INDEX([2]Лист1!$V:$V,AJ4),"") | AE4: =IFERROR(INDEX([2]Лист1!$L:$L,AJ4),"") | AF4: =IFERROR(INDEX([2]Лист1!$J:$J,AJ4),"") | AG4: =IFERROR(INDEX([2]Лист1!$K:$K,AJ4),"") | AH4: =MATCH(L4,[2]Лист1!$A:$A,0) -> 4798 | AI4: =MATCH(M4,[2]Лист1!$A:$A,0) -> #N/A | AJ4: =MATCH(N4,[2]Лист1!$A:$A,0) -> #N/A
A5: 1 | B5: ЛСР-03-05-203ТМ | C5: 3 | E5: ТЦ_18.1.06.00_50_5503095632_05.07.2022_02/ КА п.70/ ЗАО "Сибгазстройдеталь" №897 | F5: Запорная арматура По типу 1156-125-М DN 125; pmax=1.10 MPag; tmax=40 °С / °C; Раб. среда:Вода химически обессоленная; Способ управления: Ручной привод; Тип присоединения: Под приварку, Кл4Н, угл.ст. | G5: шт. | H5: 16 | I5: 226407.66 | J5: =H5*I5 -> 3622522.6 | K5: =J5/SUM($J$2:$J$1590) -> 0.028368023 | L5: 7311 | M5: =IFERROR(INDEX([1]мтр!H:H,MATCH($F5,[1]мтр!$C:$C,0)),"") | N5: =IFERROR(INDEX([1]мтр!I:I,MATCH($F5,[1]мтр!$C:$C,0)),"") | O5: =IFERROR(AVERAGE(R5,X5,AD5),"") -> 0 | P5: =IFERROR(INDEX([2]Лист1!$E:$E,AH5),"") -> 0 | Q5: =IFERROR(INDEX([2]Лист1!$I:$I,AH5),"") -> 0 | R5: =IFERROR(INDEX([2]Лист1!$V:$V,AH5),"") -> 0 | S5: =IFERROR(INDEX([2]Лист1!$L:$L,AH5),"") -> 0 | T5: =IFERROR(INDEX([2]Лист1!$J:$J,AH5),"") -> 0 | U5: =IFERROR(INDEX([2]Лист1!$K:$K,AH5),"") -> 0 | V5: =IFERROR(INDEX([2]Лист1!$E:$E,AI5),"") | W5: =IFERROR(INDEX([2]Лист1!$I:$I,AI5),"") | X5: =IFERROR(INDEX([2]Лист1!$V:$V,AI5),"") | Y5: =IFERROR(INDEX([2]Лист1!$L:$L,AI5),"") | Z5: =IFERROR(INDEX([2]Лист1!$J:$J,AI5),"") | AA5: =IFERROR(INDEX([2]Лист1!$K:$K,AI5),"") | AB5: =IFERROR(INDEX([2]Лист1!$E:$E,AJ5),"") | AC5: =IFERROR(INDEX([2]Лист1!$I:$I,AJ5),"") | AD5: =IFERROR(INDEX([2]Лист1!$V:$V,AJ5),"") | AE5: =IFERROR(INDEX([2]Лист1!$L:$L,AJ5),"") | AF5: =IFERROR(INDEX([2]Лист1!$J:$J,AJ5),"") | AG5: =IFERROR(INDEX([2]Лист1!$K:$K,AJ5),"") | AH5: =MATCH(L5,[2]Лист1!$A:$A,0) -> 6377 | AI5: =MATCH(M5,[2]Лист1!$A:$A,0) -> #N/A | AJ5: =MATCH(N5,[2]Лист1!$A:$A,0) -> #N/A
A6: 1 | B6: ЛСР-03-05-501ОВ | C6: 3 | E6: ТЦ_12.2.04.12_24_7709046921_28.03.2022_02 / КА п.1 / АО "Фирма Энергозащита" №00000000373 от 8.03.2022г. | F6: Маты прошивные из базальтового штапельного волокна МБПЭ 4-50 КТ-11, толщ=50 mm | G6: м3 | H6: 225 | I6: 10887.18 | J6: =H6*I6 -> 2449615.5 | K6: =J6/SUM($J$2:$J$1590) -> 0.019182972 | L6: =IFERROR(INDEX([1]мтр!G:G,MATCH($F6,[1]мтр!$C:$C,0)),"") -> 7501 | M6: =IFERROR(INDEX([1]мтр!H:H,MATCH($F6,[1]мтр!$C:$C,0)),"") -> 0 | N6: =IFERROR(INDEX([1]мтр!I:I,MATCH($F6,[1]мтр!$C:$C,0)),"") -> 0 | O6: =IFERROR(AVERAGE(R6,X6,AD6),"") -> 30253.766 | P6: =IFERROR(INDEX([2]Лист1!$E:$E,AH6),"") -> Маты базальтовые прошивные энергетические в обкладке из кремнеземистой ткани КТ-11 со всех сторон МБПЭ-4-50 2000.1000.50 | Q6: =IFERROR(INDEX([2]Лист1!$I:$I,AH6),"") -> м3 | R6: =IFERROR(INDEX([2]Лист1!$V:$V,AH6),"") -> 30253.766 | S6: =IFERROR(INDEX([2]Лист1!$L:$L,AH6),"") -> 44994 | T6: =IFERROR(INDEX([2]Лист1!$J:$J,AH6),"") -> АО "Фирма Энергозащита" | U6: =IFERROR(INDEX([2]Лист1!$K:$K,AH6),"") -> КП №000-000387 от 09.03.2023 | V6: =IFERROR(INDEX([2]Лист1!$E:$E,AI6),"") | W6: =IFERROR(INDEX([2]Лист1!$I:$I,AI6),"") | X6: =IFERROR(INDEX([2]Лист1!$V:$V,AI6),"") | Y6: =IFERROR(INDEX([2]Лист1!$L:$L,AI6),"") | Z6: =IFERROR(INDEX([2]Лист1!$J:$J,AI6),"") | AA6: =IFERROR(INDEX([2]Лист1!$K:$K,AI6),"") | AB6: =IFERROR(INDEX([2]Лист1!$E:$E,AJ6),"") | AC6: =IFERROR(INDEX([2]Лист1!$I:$I,AJ6),"") | AD6: =IFERROR(INDEX([2]Лист1!$V:$V,AJ6),"") | AE6: =IFERROR(INDEX([2]Лист1!$L:$L,AJ6),"") | AF6: =IFERROR(INDEX([2]Лист1!$J:$J,AJ6),"") | AG6: =IFERROR(INDEX([2]Лист1!$K:$K,AJ6),"") | AH6: =MATCH(L6,[2]Лист1!$A:$A,0) -> 6567 | AI6: =MATCH(M6,[2]Лист1!$A:$A,0) -> #N/A | AJ6: =MATCH(N6,[2]Лист1!$A:$A,0) -> #N/A
A7: 1 | B7: ЛСР-03-05-501ОВ | C7: 3 | E7: ТЦ_12.2.04.12_24_7709046921_28.03.2022_02 / КА п.1 / АО "Фирма Энергозащита" №00000000373 от 8.03.2022г. | F7: Маты прошивные из базальтового штапельного волокна МБПЭ 4-50 КТ-11, толщ=50 mm | G7: м3 | H7: 225 | I7: 10887.18 | J7: =H7*I7 -> 2449615.5 | K7: =J7/SUM($J$2:$J$1590) -> 0.019182972 | L7: =IFERROR(INDEX([1]мтр!G:G,MATCH($F7,[1]мтр!$C:$C,0)),"") -> 7501 | M7: =IFERROR(INDEX([1]мтр!H:H,MATCH($F7,[1]мтр!$C:$C,0)),"") -> 0 | N7: =IFERROR(INDEX([1]мтр!I:I,MATCH($F7,[1]мтр!$C:$C,0)),"") -> 0 | O7: =IFERROR(AVERAGE(R7,X7,AD7),"") -> 30253.766 | P7: =IFERROR(INDEX([2]Лист1!$E:$E,AH7),"") -> Маты базальтовые прошивные энергетические в обкладке из кремнеземистой ткани КТ-11 со всех сторон МБПЭ-4-50 2000.1000.50 | Q7: =IFERROR(INDEX([2]Лист1!$I:$I,AH7),"") -> м3 | R7: =IFERROR(INDEX([2]Лист1!$V:$V,AH7),"") -> 30253.766 | S7: =IFERROR(INDEX([2]Лист1!$L:$L,AH7),"") -> 44994 | T7: =IFERROR(INDEX([2]Лист1!$J:$J,AH7),"") -> АО "Фирма Энергозащита" | U7: =IFERROR(INDEX([2]Лист1!$K:$K,AH7),"") -> КП №000-000387 от 09.03.2023 | V7: =IFERROR(INDEX([2]Лист1!$E:$E,AI7),"") | W7: =IFERROR(INDEX([2]Лист1!$I:$I,AI7),"") | X7: =IFERROR(INDEX([2]Лист1!$V:$V,AI7),"") | Y7: =IFERROR(INDEX([2]Лист1!$L:$L,AI7),"") | Z7: =IFERROR(INDEX([2]Лист1!$J:$J,AI7),"") | AA7: =IFERROR(INDEX([2]Лист1!$K:$K,AI7),"") | AB7: =IFERROR(INDEX([2]Лист1!$E:$E,AJ7),"") | AC7: =IFERROR(INDEX([2]Лист1!$I:$I,AJ7),"") | AD7: =IFERROR(INDEX([2]Лист1!$V:$V,AJ7),"") | AE7: =IFERROR(INDEX([2]Лист1!$L:$L,AJ7),"") | AF7: =IFERROR(INDEX([2]Лист1!$J:$J,AJ7),"") | AG7: =IFERROR(INDEX([2]Лист1!$K:$K,AJ7),"") | AH7: =MATCH(L7,[2]Лист1!$A:$A,0) -> 6567 | AI7: =MATCH(M7,[2]Лист1!$A:$A,0) -> #N/A | AJ7: =MATCH(N7,[2]Лист1!$A:$A,0) -> #N/A
A8: 1 | B8: ЛСР-03-05-202ТМ | C8: 3 | E8: ТЦ_23.7.01.02_31_3123315768_20.05.2022_02 / КА п.2 / Энергомаш ООО "Белэнергомаш-БЗЭМ" № 006-00073 | F8: Трубопроводы низкого давления, 4Н класса безопасности, материал - нж, Дн 159х6, 133х6, 89х5_Трубопроводы из н/ж. стали низкого давления: трубопроводы Ду > 80мм | G8: т | H8: 2.94 | I8: 799960.85 | J8: =H8*I8 -> 2351884.9 | K8: =J8/SUM($J$2:$J$1590) -> 0.018417642 | L8: =IFERROR(INDEX([1]мтр!G:G,MATCH($F8,[1]мтр!$C:$C,0)),"") -> 4861 | M8: =IFERROR(INDEX([1]мтр!H:H,MATCH($F8,[1]мтр!$C:$C,0)),"") -> 0 | N8: =IFERROR(INDEX([1]мтр!I:I,MATCH($F8,[1]мтр!$C:$C,0)),"") -> 0 | O8: =IFERROR(AVERAGE(R8,X8,AD8),"") -> 2050605.2 | P8: =IFERROR(INDEX([2]Лист1!$E:$E,AH8),"") -> Трубопроводы низкого давления из нержавеющей стали зданий UJA, UKD. Объём: 40 315 616 руб. / 6 074,16 кг = 6637 RUB/кг. Транспорт 5800 USD (Договор ЕОС-закупки №629007, №7720/220816 от 07.09.2022, АСЭ_Рускон) /40DV контейнер 25 т, класс груза - 2, загрузка 85%. | Q8: =IFERROR(INDEX([2]Лист1!$I:$I,AH8),"") -> т | R8: =IFERROR(INDEX([2]Лист1!$V:$V,AH8),"") -> 2050605.2 | S8: =IFERROR(INDEX([2]Лист1!$L:$L,AH8),"") -> 44753 | T8: =IFERROR(INDEX([2]Лист1!$J:$J,AH8),"") -> Белэнергомаш-БЗЭМ | U8: =IFERROR(INDEX([2]Лист1!$K:$K,AH8),"") -> Поставка трубопроводов по лоту 19677-248 Куд3;4. НМЦ от 11.07.2022, рассчитанная на основании п.1 раздела 3 главы 3 (приложения №8 к ЕОСЗ). | V8: =IFERROR(INDEX([2]Лист1!$E:$E,AI8),"") | W8: =IFERROR(INDEX([2]Лист1!$I:$I,AI8),"") | X8: =IFERROR(INDEX([2]Лист1!$V:$V,AI8),"") | Y8: =IFERROR(INDEX([2]Лист1!$L:$L,AI8),"") | Z8: =IFERROR(INDEX([2]Лист1!$J:$J,AI8),"") | AA8: =IFERROR(INDEX([2]Лист1!$K:$K,AI8),"") | AB8: =IFERROR(INDEX([2]Лист1!$E:$E,AJ8),"") | AC8: =IFERROR(INDEX([2]Лист1!$I:$I,AJ8),"") | AD8: =IFERROR(INDEX([2]Лист1!$V:$V,AJ8),"") | AE8: =IFERROR(INDEX([2]Лист1!$L:$L,AJ8),"") | AF8: =IFERROR(INDEX([2]Лист1!$J:$J,AJ8),"") | AG8: =IFERROR(INDEX([2]Лист1!$K:$K,AJ8),"") | AH8: =MATCH(L8,[2]Лист1!$A:$A,0) -> 4798 | AI8: =MATCH(M8,[2]Лист1!$A:$A,0) -> #N/A | AJ8: =MATCH(N8,[2]Лист1!$A:$A,0) -> #N/A
A9: 1 | B9: ЛСР-03-05-701АК | C9: 3 | E9: ТЦ_20.2.03.02_50_7710050305_31.05.2022_02 | F9: Опорная конструкция T MQK-600. Hilti 4; III; QNC | G9: шт. | H9: 1592 | I9: 1422.48 | J9: =H9*I9 -> 2264588.2 | K9: =J9/SUM($J$2:$J$1590) -> 0.01773402 | L9: =IFERROR(INDEX([1]мтр!G:G,MATCH($F9,[1]мтр!$C:$C,0)),"") -> 7609 | M9: =IFERROR(INDEX([1]мтр!H:H,MATCH($F9,[1]мтр!$C:$C,0)),"") -> 0 | N9: =IFERROR(INDEX([1]мтр!I:I,MATCH($F9,[1]мтр!$C:$C,0)),"") -> 0 | O9: =IFERROR(AVERAGE(R9,X9,AD9),"") -> 2697.7432 | P9: =IFERROR(INDEX([2]Лист1!$E:$E,AH9),"") -> Опорная конструкция T MQK-600 в составе:- консольная опора MQK-72/600 #369616, 1 шт;- анкер для тяжелых нагрузок HSL4-G M8 d12x92 5/-/- #2237458, 2 шт. Транспорт экспертно 5% | Q9: =IFERROR(INDEX([2]Лист1!$I:$I,AH9),"") -> шт. | R9: =IFERROR(INDEX([2]Лист1!$V:$V,AH9),"") -> 2697.7432 | S9: =IFERROR(INDEX([2]Лист1!$L:$L,AH9),"") -> 45013 | T9: =IFERROR(INDEX([2]Лист1!$J:$J,AH9),"") -> Hilti Italy | U9: =IFERROR(INDEX([2]Лист1!$K:$K,AH9),"") -> https://www.hilti.it/c/CLS_INSTALLATION_SYS_7134/CLS_SPRINKLER_7134/CLS_SPRINKLER_COMPONENTS_7134/r4345https://www.hilti.it/?CHA_GLOBAL_ANC_SIZE=M8&CHD_ANCHOR_LENGTH=102%20mm&combo_content=51979bb59b0ce01b4fe329858c7e0028&salespackquantity=40%20pezzi&itemCode=371793 | V9: =IFERROR(INDEX([2]Лист1!$E:$E,AI9),"") | W9: =IFERROR(INDEX([2]Лист1!$I:$I,AI9),"") | X9: =IFERROR(INDEX([2]Лист1!$V:$V,AI9),"") | Y9: =IFERROR(INDEX([2]Лист1!$L:$L,AI9),"") | Z9: =IFERROR(INDEX([2]Лист1!$J:$J,AI9),"") | AA9: =IFERROR(INDEX([2]Лист1!$K:$K,AI9),"") | AB9: =IFERROR(INDEX([2]Лист1!$E:$E,AJ9),"") | AC9: =IFERROR(INDEX([2]Лист1!$I:$I,AJ9),"") | AD9: =IFERROR(INDEX([2]Лист1!$V:$V,AJ9),"") | AE9: =IFERROR(INDEX([2]Лист1!$L:$L,AJ9),"") | AF9: =IFERROR(INDEX([2]Лист1!$J:$J,AJ9),"") | AG9: =IFERROR(INDEX([2]Лист1!$K:$K,AJ9),"") | AH9: =MATCH(L9,[2]Лист1!$A:$A,0) -> 6675 | AI9: =MATCH(M9,[2]Лист1!$A:$A,0) -> #N/A | AJ9: =MATCH(N9,[2]Лист1!$A:$A,0) -> #N/A
A10: 1 | B10: ЛСР-03-05-101C | C10: 3 | E10: 08.4.03.03-0009 | F10: Сталь арматурная рифленая свариваемая, класс A500С, диаметр 25 мм_А500C (d20- d32) | G10: т | H10: 394 | I10: 5488.69 | J10: =H10*I10 -> 2162543.9 | K10: =J10/SUM($J$2:$J$1590) -> 0.01693491 | L10: =IFERROR(INDEX([1]мтр!G:G,MATCH($F10,[1]мтр!$C:$C,0)),"") -> 7509 | M10: =IFERROR(INDEX([1]мтр!H:H,MATCH($F10,[1]мтр!$C:$C,0)),"") -> 0 | N10: =IFERROR(INDEX([1]мтр!I:I,MATCH($F10,[1]мтр!$C:$C,0)),"") -> 0 | O10: =IFERROR(AVERAGE(R10,X10,AD10),"") -> 16541.58 | P10: =IFERROR(INDEX([2]Лист1!$E:$E,AH10),"") -> Арматура стальная периодического профиля, класс B500DWR, диаметр 6 - 40 мм | Q10: =IFERROR(INDEX([2]Лист1!$I:$I,AH10),"") -> т | R10: =IFERROR(INDEX([2]Лист1!$V:$V,AH10),"") -> 16541.58 | S10: =IFERROR(INDEX([2]Лист1!$L:$L,AH10),"") -> 44984 | T10: =IFERROR(INDEX([2]Лист1!$J:$J,AH10),"") -> N/A | U10: =IFERROR(INDEX([2]Лист1!$K:$K,AH10),"") -> Справочник сметных цен на строильные материалы, изделия и конструкции для строительства АЭС Эль-Дабаа, Арабская республика Египет. III квартал 2022 года, ГК Росатом №05-0077 | V10: =IFERROR(INDEX([2]Лист1!$E:$E,AI10),"") | W10: =IFERROR(INDEX([2]Лист1!$I:$I,AI10),"") | X10: =IFERROR(INDEX([2]Лист1!$V:$V,AI10),"") | Y10: =IFERROR(INDEX([2]Лист1!$L:$L,AI10),"") | Z10: =IFERROR(INDEX([2]Лист1!$J:$J,AI10),"") | AA10: =IFERROR(INDEX([2]Лист1!$K:$K,AI10),"") | AB10: =IFERROR(INDEX([2]Лист1!$E:$E,AJ10),"") | AC10: =IFERROR(INDEX([2]Лист1!$I:$I,AJ10),"") | AD10: =IFERROR(INDEX([2]Лист1!$V:$V,AJ10),"") | AE10: =IFERROR(INDEX([2]Лист1!$L:$L,AJ10),"") | AF10: =IFERROR(INDEX([2]Лист1!$J:$J,AJ10),"") | AG10: =IFERROR(INDEX([2]Лист1!$K:$K,AJ10),"") | AH10: =MATCH(L10,[2]Лист1!$A:$A,0) -> 6575 | AI10: =MATCH(M10,[2]Лист1!$A:$A,0) -> #N/A | AJ10: =MATCH(N10,[2]Лист1!$A:$A,0) -> #N/A
A11: 1 | B11: ЛСР-03-05-101C | C11: 3 | E11: 04.1.02.02-0014 | F11: Смеси бетонные тяжелого бетона (БСТ) для гидротехнических сооружений на сульфатостойких цементах, класс В45 (М600)_B45 W8 | G11: м3 | H11: 1588.28 | I11: 1339.78 | J11: =H11*I11 -> 2127945.8 | K11: =J11/SUM($J$2:$J$1590) -> 0.016663972 | L11: =IFERROR(INDEX([1]мтр!G:G,MATCH($F11,[1]мтр!$C:$C,0)),"") -> 5710 | M11: =IFERROR(INDEX([1]мтр!H:H,MATCH($F11,[1]мтр!$C:$C,0)),"") -> 0 | N11: =IFERROR(INDEX([1]мтр!I:I,MATCH($F11,[1]мтр!$C:$C,0)),"") -> 0 | O11: =IFERROR(AVERAGE(R11,X11,AD11),"") -> 2207.07 | P11: =IFERROR(INDEX([2]Лист1!$E:$E,AH11),"") -> Бетон тяжелый на сульфатостойком портландцементе, класс В45 П5 W8 SRC XS3, XA3 | Q11: =IFERROR(INDEX([2]Лист1!$I:$I,AH11),"") -> м3 | R11: =IFERROR(INDEX([2]Лист1!$V:$V,AH11),"") -> 2207.07 | S11: =IFERROR(INDEX([2]Лист1!$L:$L,AH11),"") -> 44872 | T11: =IFERROR(INDEX([2]Лист1!$J:$J,AH11),"") -> N/A | U11: =IFERROR(INDEX([2]Лист1!$K:$K,AH11),"") -> Справочник сметных цен на строильные материалы, изделия и конструкции для строительства АЭС Эль-Дабаа, Арабская республика Египет. II квартал 2022 года, ГК Росатом №05-0070 | V11: =IFERROR(INDEX([2]Лист1!$E:$E,AI11),"") | W11: =IFERROR(INDEX([2]Лист1!$I:$I,AI11),"") | X11: =IFERROR(INDEX([2]Лист1!$V:$V,AI11),"") | Y11: =IFERROR(INDEX([2]Лист1!$L:$L,AI11),"") | Z11: =IFERROR(INDEX([2]Лист1!$J:$J,AI11),"") | AA11: =IFERROR(INDEX([2]Лист1!$K:$K,AI11),"") | AB11: =IFERROR(INDEX([2]Лист1!$E:$E,AJ11),"") | AC11: =IFERROR(INDEX([2]Лист1!$I:$I,AJ11),"") | AD11: =IFERROR(INDEX([2]Лист1!$V:$V,AJ11),"") | AE11: =IFERROR(INDEX([2]Лист1!$L:$L,AJ11),"") | AF11: =IFERROR(INDEX([2]Лист1!$J:$J,AJ11),"") | AG11: =IFERROR(INDEX([2]Лист1!$K:$K,AJ11),"") | AH11: =MATCH(L11,[2]Лист1!$A:$A,0) -> 463 | AI11: =MATCH(M11,[2]Лист1!$A:$A,0) -> #N/A | AJ11: =MATCH(N11,[2]Лист1!$A:$A,0) -> #N/A
A12: 1 | B12: ЛСР-03-05-206ТМ | C12: 3 | E12: ТЦ_23.7.01.02_31_3123315768_20.05.2022_02/ КА п.78/ ООО "Белэнергомаш-БЗЭМ" №006-00073 | F12: Трубопроводы низкого давления из нержавеющей стали, 4 класса безопасности, Ду>80мм_ DN 150 мм, DN 125 мм | G12: т | H12: 2.651 | I12: 799960.85 | J12: =H12*I12 -> 2120696.2 | K12: =J12/SUM($J$2:$J$1590) -> 0.016607201 | L12: =IFERROR(INDEX([1]мтр!G:G,MATCH($F12,[1]мтр!$C:$C,0)),"") -> 4861 | M12: =IFERROR(INDEX([1]мтр!H:H,MATCH($F12,[1]мтр!$C:$C,0)),"") -> 0 | N12: =IFERROR(INDEX([1]мтр!I:I,MATCH($F12,[1]мтр!$C:$C,0)),"") -> 0 | O12: =IFERROR(AVERAGE(R12,X12,AD12),"") -> 2050605.2 | P12: =IFERROR(INDEX([2]Лист1!$E:$E,AH12),"") -> Трубопроводы низкого давления из нержавеющей стали зданий UJA, UKD. Объём: 40 315 616 руб. / 6 074,16 кг = 6637 RUB/кг. Транспорт 5800 USD (Договор ЕОС-закупки №629007, №7720/220816 от 07.09.2022, АСЭ_Рускон) /40DV контейнер 25 т, класс груза - 2, загрузка 85%. | Q12: =IFERROR(INDEX([2]Лист1!$I:$I,AH12),"") -> т | R12: =IFERROR(INDEX([2]Лист1!$V:$V,AH12),"") -> 2050605.2 | S12: =IFERROR(INDEX([2]Лист1!$L:$L,AH12),"") -> 44753 | T12: =IFERROR(INDEX([2]Лист1!$J:$J,AH12),"") -> Белэнергомаш-БЗЭМ | U12: =IFERROR(INDEX([2]Лист1!$K:$K,AH12),"") -> Поставка трубопроводов по лоту 19677-248 Куд3;4. НМЦ от 11.07.2022, рассчитанная на основании п.1 раздела 3 главы 3 (приложения №8 к ЕОСЗ). | V12: =IFERROR(INDEX([2]Лист1!$E:$E,AI12),"") | W12: =IFERROR(INDEX([2]Лист1!$I:$I,AI12),"") | X12: =IFERROR(INDEX([2]Лист1!$V:$V,AI12),"") | Y12: =IFERROR(INDEX([2]Лист1!$L:$L,AI12),"") | Z12: =IFERROR(INDEX([2]Лист1!$J:$J,AI12),"") | AA12: =IFERROR(INDEX([2]Лист1!$K:$K,AI12),"") | AB12: =IFERROR(INDEX([2]Лист1!$E:$E,AJ12),"") | AC12: =IFERROR(INDEX([2]Лист1!$I:$I,AJ12),"") | AD12: =IFERROR(INDEX([2]Лист1!$V:$V,AJ12),"") | AE12: =IFERROR(INDEX([2]Лист1!$L:$L,AJ12),"") | AF12: =IFERROR(INDEX([2]Лист1!$J:$J,AJ12),"") | AG12: =IFERROR(INDEX([2]Лист1!$K:$K,AJ12),"") | AH12: =MATCH(L12,[2]Лист1!$A:$A,0) -> 4798 | AI12: =MATCH(M12,[2]Лист1!$A:$A,0) -> #N/A | AJ12: =MATCH(N12,[2]Лист1!$A:$A,0) -> #N/A
A13: 1 | B13: ЛСР-03-05-101C | C13: 3 | E13: 04.1.02.05-0011 | F13: Смеси бетонные тяжелого бетона (БСТ), класс В30 (М400)_В30 W8 | G13: м3 | H13: 2430.925 | I13: 811.26 | J13: =H13*I13 -> 1972112.2 | K13: =J13/SUM($J$2:$J$1590) -> 0.015443637 | L13: =IFERROR(INDEX([1]мтр!G:G,MATCH($F13,[1]мтр!$C:$C,0)),"") -> 5177 | M13: =IFERROR(INDEX([1]мтр!H:H,MATCH($F13,[1]мтр!$C:$C,0)),"") -> 5178 | N13: =IFERROR(INDEX([1]мтр!I:I,MATCH($F13,[1]мтр!$C:$C,0)),"") -> 0 | O13: =IFERROR(AVERAGE(R13,X13,AD13),"") -> 1831.03 | P13: =IFERROR(INDEX([2]Лист1!$E:$E,AH13),"") -> Бетон тяжелый, класс C35 CEM I | Q13: =IFERROR(INDEX([2]Лист1!$I:$I,AH13),"") -> м3 | R13: =IFERROR(INDEX([2]Лист1!$V:$V,AH13),"") -> 1813.6704 | S13: =IFERROR(INDEX([2]Лист1!$L:$L,AH13),"") -> 44735 | T13: =IFERROR(INDEX([2]Лист1!$J:$J,AH13),"") -> Nuclear Concrete Mixes | U13: =IFERROR(INDEX([2]Лист1!$K:$K,AH13),"") -> ТКП 04-N-161 от 23.06.2022 | V13: =IFERROR(INDEX([2]Лист1!$E:$E,AI13),"") -> Бетон тяжелый, класс C35 CEM I | W13: =IFERROR(INDEX([2]Лист1!$I:$I,AI13),"") -> м3 | X13: =IFERROR(INDEX([2]Лист1!$V:$V,AI13),"") -> 1848.3896 | Y13: =IFERROR(INDEX([2]Лист1!$L:$L,AI13),"") -> 44738 | Z13: =IFERROR(INDEX([2]Лист1!$J:$J,AI13),"") -> 3S READY MIX | AA13: =IFERROR(INDEX([2]Лист1!$K:$K,AI13),"") -> ТКП от 26.06.2022 | AB13: =IFERROR(INDEX([2]Лист1!$E:$E,AJ13),"") | AC13: =IFERROR(INDEX([2]Лист1!$I:$I,AJ13),"") | AD13: =IFERROR(INDEX([2]Лист1!$V:$V,AJ13),"") | AE13: =IFERROR(INDEX([2]Лист1!$L:$L,AJ13),"") | AF13: =IFERROR(INDEX([2]Лист1!$J:$J,AJ13),"") | AG13: =IFERROR(INDEX([2]Лист1!$K:$K,AJ13),"") | AH13: =MATCH(L13,[2]Лист1!$A:$A,0) -> 4854 | AI13: =MATCH(M13,[2]Лист1!$A:$A,0) -> 4855 | AJ13: =MATCH(N13,[2]Лист1!$A:$A,0) -> #N/A
A14: 1 | B14: ЛСР-03-05-602Э | C14: 3 | E14: 21.1.06.10-0142 | F14: Кабель силовой с медными жилами ПвПнг(A)-FRHF 5х95-1000_Кабель силовой 5х95мм2-1кВ | G14: 1000 м | H14: 2.856 | I14: 688756.52 | J14: =H14*I14 -> 1967088.6 | K14: =J14/SUM($J$2:$J$1590) -> 0.015404297 | L14: =IFERROR(INDEX([1]мтр!G:G,MATCH($F14,[1]мтр!$C:$C,0)),"") -> 5263 | M14: =IFERROR(INDEX([1]мтр!H:H,MATCH($F14,[1]мтр!$C:$C,0)),"") -> 0 | N14: =IFERROR(INDEX([1]мтр!I:I,MATCH($F14,[1]мтр!$C:$C,0)),"") -> 0 | O14: =IFERROR(AVERAGE(R14,X14,AD14),"") -> 1051715.2 | P14: =IFERROR(INDEX([2]Лист1!$E:$E,AH14),"") -> Импорт из РФ_ПвПнг(А)-HF 5х95мс(N,PE)-1 кВ ТУ 16.К71-341-2004 (ГОСТ 31996-2012), в контейнере 4 барабанов №18, на барабане= 0,55 км кабеля. Транспорт контейнер:1) автомобильный Москва - Новорос.: 1540 км х 70руб/км;2) таможенное оформление РФ: 34 830 руб;3) портовая обработка и фрахт до Александрии: 273 800 руб;4) портовая обработка и таможенное оформление в Александрии: 1250 EGP;5) автомобильный Александрия - площадка: 6200 EGPИст. 1-3: согл НМЦ РосСЭМ от 17.01.2022, 4-5: инф Филиал от 20.01.2022. | Q14: =IFERROR(INDEX([2]Лист1!$I:$I,AH14),"") -> 1000 м | R14: =IFERROR(INDEX([2]Лист1!$V:$V,AH14),"") -> 1051715.2 | S14: =IFERROR(INDEX([2]Лист1!$L:$L,AH14),"") -> 44571 | T14: =IFERROR(INDEX([2]Лист1!$J:$J,AH14),"") -> Электрокабель | U14: =IFERROR(INDEX([2]Лист1!$K:$K,AH14),"") -> Прайс-лист Электрокабель от 10.01.2022 | V14: =IFERROR(INDEX([2]Лист1!$E:$E,AI14),"") | W14: =IFERROR(INDEX([2]Лист1!$I:$I,AI14),"") | X14: =IFERROR(INDEX([2]Лист1!$V:$V,AI14),"") | Y14: =IFERROR(INDEX([2]Лист1!$L:$L,AI14),"") | Z14: =IFERROR(INDEX([2]Лист1!$J:$J,AI14),"") | AA14: =IFERROR(INDEX([2]Лист1!$K:$K,AI14),"") | AB14: =IFERROR(INDEX([2]Лист1!$E:$E,AJ14),"") | AC14: =IFERROR(INDEX([2]Лист1!$I:$I,AJ14),"") | AD14: =IFERROR(INDEX([2]Лист1!$V:$V,AJ14),"") | AE14: =IFERROR(INDEX([2]Лист1!$L:$L,AJ14),"") | AF14: =IFERROR(INDEX([2]Лист1!$J:$J,AJ14),"") | AG14: =IFERROR(INDEX([2]Лист1!$K:$K,AJ14),"") | AH14: =MATCH(L14,[2]Лист1!$A:$A,0) -> 2364 | AI14: =MATCH(M14,[2]Лист1!$A:$A,0) -> #N/A | AJ14: =MATCH(N14,[2]Лист1!$A:$A,0) -> #N/A
A15: 1 | B15: ЛСР-03-05-203ТМ | C15: 3 | E15: ТЦ_18.2.08.00_50_5503095632_05.07.2022_02 / КА п.24/ ЗАО "Сибгазстройдеталь" №897 | F15: Фильтр механический По типу ФС 100 С 16-0.4У DN 100; pmax=0.12 MPag; tmax=109 °С; Раб. среда: Вода питательная ПРК; Q=217 м?/ч; H-высота = 235 мм; L-длина = 350 мм; W-ширина = 169 мм, Кл 4Н_ФС100/16П-200-Ф1-Д1-УХЛ 1; ФС- фильтр сливной 100-номинальный диаметр, DN 16-давление 16 кг/см2 или (1,6Мпа) | G15: шт. | H15: 5 | I15: 363366.32 | J15: =H15*I15 -> 1816831.6 | K15: =J15/SUM($J$2:$J$1590) -> 0.014227633 | L15: =IFERROR(INDEX([1]мтр!G:G,MATCH($F15,[1]мтр!$C:$C,0)),"") | M15: =IFERROR(INDEX([1]мтр!H:H,MATCH($F15,[1]мтр!$C:$C,0)),"") | N15: =IFERROR(INDEX([1]мтр!I:I,MATCH($F15,[1]мтр!$C:$C,0)),"") | O15: =IFERROR(AVERAGE(R15,X15,AD15),"") | P15: =IFERROR(INDEX([2]Лист1!$E:$E,AH15),"") | Q15: =IFERROR(INDEX([2]Лист1!$I:$I,AH15),"") | R15: =IFERROR(INDEX([2]Лист1!$V:$V,AH15),"") | S15: =IFERROR(INDEX([2]Лист1!$L:$L,AH15),"") | T15: =IFERROR(INDEX([2]Лист1!$J:$J,AH15),"") | U15: =IFERROR(INDEX([2]Лист1!$K:$K,AH15),"") | V15: =IFERROR(INDEX([2]Лист1!$E:$E,AI15),"") | W15: =IFERROR(INDEX([2]Лист1!$I:$I,AI15),"") | X15: =IFERROR(INDEX([2]Лист1!$V:$V,AI15),"") | Y15: =IFERROR(INDEX([2]Лист1!$L:$L,AI15),"") | Z15: =IFERROR(INDEX([2]Лист1!$J:$J,AI15),"") | AA15: =IFERROR(INDEX([2]Лист1!$K:$K,AI15),"") | AB15: =IFERROR(INDEX([2]Лист1!$E:$E,AJ15),"") | AC15: =IFERROR(INDEX([2]Лист1!$I:$I,AJ15),"") | AD15: =IFERROR(INDEX([2]Лист1!$V:$V,AJ15),"") | AE15: =IFERROR(INDEX([2]Лист1!$L:$L,AJ15),"") | AF15: =IFERROR(INDEX([2]Лист1!$J:$J,AJ15),"") | AG15: =IFERROR(INDEX([2]Лист1!$K:$K,AJ15),"") | AH15: =MATCH(L15,[2]Лист1!$A:$A,0) -> #N/A | AI15: =MATCH(M15,[2]Лист1!$A:$A,0) -> #N/A | AJ15: =MATCH(N15,[2]Лист1!$A:$A,0) -> #N/A
A16: 1 | B16: ЛСР-03-05-102С | C16: 3 | E16: 14.5.04.06-0006 | F16: Мастика кровельная двухкомпонентная полиуретановая | G16: т | H16: 101.2284 | I16: 16460.67 | J16: =H16*I16 -> 1666287.3 | K16: =J16/SUM($J$2:$J$1590) -> 0.013048718 | L16: 5813 | M16: =IFERROR(INDEX([1]мтр!H:H,MATCH($F16,[1]мтр!$C:$C,0)),"") | N16: =IFERROR(INDEX([1]мтр!I:I,MATCH($F16,[1]мтр!$C:$C,0)),"") | O16: =IFERROR(AVERAGE(R16,X16,AD16),"") -> 27434.4 | P16: =IFERROR(INDEX([2]Лист1!$E:$E,AH16),"") -> Мастика МББП-65 (ЛИЛО-1) ГОСТ 32870-2014 /Мастика бутилкаучуковая холодная | Q16: =IFERROR(INDEX([2]Лист1!$I:$I,AH16),"") -> т | R16: =IFERROR(INDEX([2]Лист1!$V:$V,AH16),"") -> 27434.4 | S16: =IFERROR(INDEX([2]Лист1!$L:$L,AH16),"") -> 44900 | T16: =IFERROR(INDEX([2]Лист1!$J:$J,AH16),"") -> ООО "УРАЛЬСКИЙ БИТУМНЫЙ ЗАВОД", | U16: =IFERROR(INDEX([2]Лист1!$K:$K,AH16),"") -> ООО "УРАЛЬСКИЙ БИТУМНЫЙ ЗАВОД", | V16: =IFERROR(INDEX([2]Лист1!$E:$E,AI16),"") | W16: =IFERROR(INDEX([2]Лист1!$I:$I,AI16),"") | X16: =IFERROR(INDEX([2]Лист1!$V:$V,AI16),"") | Y16: =IFERROR(INDEX([2]Лист1!$L:$L,AI16),"") | Z16: =IFERROR(INDEX([2]Лист1!$J:$J,AI16),"") | AA16: =IFERROR(INDEX([2]Лист1!$K:$K,AI16),"") | AB16: =IFERROR(INDEX([2]Лист1!$E:$E,AJ16),"") | AC16: =IFERROR(INDEX([2]Лист1!$I:$I,AJ16),"") | AD16: =IFERROR(INDEX([2]Лист1!$V:$V,AJ16),"") | AE16: =IFERROR(INDEX([2]Лист1!$L:$L,AJ16),"") | AF16: =IFERROR(INDEX([2]Лист1!$J:$J,AJ16),"") | AG16: =IFERROR(INDEX([2]Лист1!$K:$K,AJ16),"") | AH16: =MATCH(L16,[2]Лист1!$A:$A,0) -> 4962 | AI16: =MATCH(M16,[2]Лист1!$A:$A,0) -> #N/A | AJ16: =MATCH(N16,[2]Лист1!$A:$A,0) -> #N/A
A17: 1 | B17: ЛСР-03-05-206ТМ | C17: 3 | E17: 14.5.09.10-0001 | F17: Толуол каменноугольный и сланцевый, марка А | G17: т | H17: 385 | I17: 3922 | J17: =H17*I17 -> 1509970 | K17: =J17/SUM($J$2:$J$1590) -> 0.011824595 | L17: =IFERROR(INDEX([1]мтр!G:G,MATCH($F17,[1]мтр!$C:$C,0)),"") -> 7163 | M17: =IFERROR(INDEX([1]мтр!H:H,MATCH($F17,[1]мтр!$C:$C,0)),"") -> 0 | N17: =IFERROR(INDEX([1]мтр!I:I,MATCH($F17,[1]мтр!$C:$C,0)),"") -> 0 | O17: =IFERROR(AVERAGE(R17,X17,AD17),"") -> 110509.64 | P17: =IFERROR(INDEX([2]Лист1!$E:$E,AH17),"") -> Толуол нефтяной ГОСТ 14710-78 | Q17: =IFERROR(INDEX([2]Лист1!$I:$I,AH17),"") -> т | R17: =IFERROR(INDEX([2]Лист1!$V:$V,AH17),"") -> 110509.64 | S17: =IFERROR(INDEX([2]Лист1!$L:$L,AH17),"") -> 44937 | T17: =IFERROR(INDEX([2]Лист1!$J:$J,AH17),"") -> ООО "УФАХИМКОМПЛЕКТ" | U17: =IFERROR(INDEX([2]Лист1!$K:$K,AH17),"") -> ЕОС Закупки (665497) №4163/2022/10.1-ДОГ от 11.01.2023 | V17: =IFERROR(INDEX([2]Лист1!$E:$E,AI17),"") | W17: =IFERROR(INDEX([2]Лист1!$I:$I,AI17),"") | X17: =IFERROR(INDEX([2]Лист1!$V:$V,AI17),"") | Y17: =IFERROR(INDEX([2]Лист1!$L:$L,AI17),"") | Z17: =IFERROR(INDEX([2]Лист1!$J:$J,AI17),"") | AA17: =IFERROR(INDEX([2]Лист1!$K:$K,AI17),"") | AB17: =IFERROR(INDEX([2]Лист1!$E:$E,AJ17),"") | AC17: =IFERROR(INDEX([2]Лист1!$I:$I,AJ17),"") | AD17: =IFERROR(INDEX([2]Лист1!$V:$V,AJ17),"") | AE17: =IFERROR(INDEX([2]Лист1!$L:$L,AJ17),"") | AF17: =IFERROR(INDEX([2]Лист1!$J:$J,AJ17),"") | AG17: =IFERROR(INDEX([2]Лист1!$K:$K,AJ17),"") | AH17: =MATCH(L17,[2]Лист1!$A:$A,0) -> 6229 | AI17: =MATCH(M17,[2]Лист1!$A:$A,0) -> #N/A | AJ17: =MATCH(N17,[2]Лист1!$A:$A,0) -> #N/A
A18: 1 | B18: ЛСР-03-05-203ТМ | C18: 3 | E18: ТЦ_18.1.06.00_50_5503095632_05.07.2022_02 /КА п.51/ ЗАО "Сибгазстройдеталь" №897 | F18: Запорная арматура По типу 2с-27-2Н DN 200; pmax=0.40 MPag; tmax=155 °С / °C; Раб. среда:Пар собственных нужд; Способ управления: Ручной привод; Тип присоединения: Под приварку, Кл.4Н, угл.ст | G18: шт. | H18: 10 | I18: 147436.32 | J18: =H18*I18 -> 1474363.2 | K18: =J18/SUM($J$2:$J$1590) -> 0.011545758 | L18: =IFERROR(INDEX([1]мтр!G:G,MATCH($F18,[1]мтр!$C:$C,0)),"") | M18: =IFERROR(INDEX([1]мтр!H:H,MATCH($F18,[1]мтр!$C:$C,0)),"") | N18: =IFERROR(INDEX([1]мтр!I:I,MATCH($F18,[1]мтр!$C:$C,0)),"") | O18: =IFERROR(AVERAGE(R18,X18,AD18),"") | P18: =IFERROR(INDEX([2]Лист1!$E:$E,AH18),"") | Q18: =IFERROR(INDEX([2]Лист1!$I:$I,AH18),"") | R18: =IFERROR(INDEX([2]Лист1!$V:$V,AH18),"") | S18: =IFERROR(INDEX([2]Лист1!$L:$L,AH18),"") | T18: =IFERROR(INDEX([2]Лист1!$J:$J,AH18),"") | U18: =IFERROR(INDEX([2]Лист1!$K:$K,AH18),"") | V18: =IFERROR(INDEX([2]Лист1!$E:$E,AI18),"") | W18: =IFERROR(INDEX([2]Лист1!$I:$I,AI18),"") | X18: =IFERROR(INDEX([2]Лист1!$V:$V,AI18),"") | Y18: =IFERROR(INDEX([2]Лист1!$L:$L,AI18),"") | Z18: =IFERROR(INDEX([2]Лист1!$J:$J,AI18),"") | AA18: =IFERROR(INDEX([2]Лист1!$K:$K,AI18),"") | AB18: =IFERROR(INDEX([2]Лист1!$E:$E,AJ18),"") | AC18: =IFERROR(INDEX([2]Лист1!$I:$I,AJ18),"") | AD18: =IFERROR(INDEX([2]Лист1!$V:$V,AJ18),"") | AE18: =IFERROR(INDEX([2]Лист1!$L:$L,AJ18),"") | AF18: =IFERROR(INDEX([2]Лист1!$J:$J,AJ18),"") | AG18: =IFERROR(INDEX([2]Лист1!$K:$K,AJ18),"") | AH18: =MATCH(L18,[2]Лист1!$A:$A,0) -> #N/A | AI18: =MATCH(M18,[2]Лист1!$A:$A,0) -> #N/A | AJ18: =MATCH(N18,[2]Лист1!$A:$A,0) -> #N/A
A19: 1 | B19: ЛСР-03-05-206ТМ | C19: 3 | E19: ТЦ_23.7.01.02_31_3123315768_20.05.2022_02/ КА п.76/ ООО "Белэнергомаш-БЗЭМ" №006-00073 | F19: Трубопроводы низкого давления из углеродистой стали, 4 класса безопасности, Ду > 80мм_ DN350 мм, DN300 мм, DN200, DN100 | G19: т | H19: 6.957 | I19: 211499.32 | J19: =H19*I19 -> 1471400.8 | K19: =J19/SUM($J$2:$J$1590) -> 0.011522559 | L19: =IFERROR(INDEX([1]мтр!G:G,MATCH($F19,[1]мтр!$C:$C,0)),"") -> 4859 | M19: =IFERROR(INDEX([1]мтр!H:H,MATCH($F19,[1]мтр!$C:$C,0)),"") -> 0 | N19: =IFERROR(INDEX([1]мтр!I:I,MATCH($F19,[1]мтр!$C:$C,0)),"") -> 0 | O19: =IFERROR(AVERAGE(R19,X19,AD19),"") -> 479788.26 | P19: =IFERROR(INDEX([2]Лист1!$E:$E,AH19),"") -> Трубопроводы низкого давления из углеродистой стали зданий UJA, UKD. Объём: 4526466 руб. / 2939,52 кг = 1540 RUB/кг. Транспорт 5800 USD (Договор ЕОС-закупки №629007, №7720/220816 от 07.09.2022, АСЭ_Рускон) /40DV контейнер 25 т, класс груза - 2, загрузка 85%. | Q19: =IFERROR(INDEX([2]Лист1!$I:$I,AH19),"") -> т | R19: =IFERROR(INDEX([2]Лист1!$V:$V,AH19),"") -> 479788.26 | S19: =IFERROR(INDEX([2]Лист1!$L:$L,AH19),"") -> 44753 | T19: =IFERROR(INDEX([2]Лист1!$J:$J,AH19),"") -> Белэнергомаш-БЗЭМ | U19: =IFERROR(INDEX([2]Лист1!$K:$K,AH19),"") -> Поставка трубопроводов по лоту 19677-248 Куд3;4. НМЦ от 11.07.2022, рассчитанная на основании п.1 раздела 3 главы 3 (приложения №8 к ЕОСЗ). | V19: =IFERROR(INDEX([2]Лист1!$E:$E,AI19),"") | W19: =IFERROR(INDEX([2]Лист1!$I:$I,AI19),"") | X19: =IFERROR(INDEX([2]Лист1!$V:$V,AI19),"") | Y19: =IFERROR(INDEX([2]Лист1!$L:$L,AI19),"") | Z19: =IFERROR(INDEX([2]Лист1!$J:$J,AI19),"") | AA19: =IFERROR(INDEX([2]Лист1!$K:$K,AI19),"") | AB19: =IFERROR(INDEX([2]Лист1!$E:$E,AJ19),"") | AC19: =IFERROR(INDEX([2]Лист1!$I:$I,AJ19),"") | AD19: =IFERROR(INDEX([2]Лист1!$V:$V,AJ19),"") | AE19: =IFERROR(INDEX([2]Лист1!$L:$L,AJ19),"") | AF19: =IFERROR(INDEX([2]Лист1!$J:$J,AJ19),"") | AG19: =IFERROR(INDEX([2]Лист1!$K:$K,AJ19),"") | AH19: =MATCH(L19,[2]Лист1!$A:$A,0) -> 4796 | AI19: =MATCH(M19,[2]Лист1!$A:$A,0) -> #N/A | AJ19: =MATCH(N19,[2]Лист1!$A:$A,0) -> #N/A
A20: 1 | B20: ЛСР-03-05-103С | C20: 3 | E20: 07.2.07.13-0161 | F20: Площадки просадочные, мостики, кронштейны, маршевые лестницы, пожарные щиты переходных площадок, ограждений | G20: т | H20: 117.866 | I20: 11879.76 | J20: =H20*I20 -> 1400219.8 | K20: =J20/SUM($J$2:$J$1590) -> 0.01096514 | L20: =IFERROR(INDEX([1]мтр!G:G,MATCH($F20,[1]мтр!$C:$C,0)),"") -> 7590 | M20: =IFERROR(INDEX([1]мтр!H:H,MATCH($F20,[1]мтр!$C:$C,0)),"") -> 7591 | N20: =IFERROR(INDEX([1]мтр!I:I,MATCH($F20,[1]мтр!$C:$C,0)),"") -> 0 | O20: =IFERROR(AVERAGE(R20,X20,AD20),"") -> 49555.459 | P20: =IFERROR(INDEX([2]Лист1!$E:$E,AH20),"") -> Усредненная цена готовых металлоконструкций (на примере здания ЦЕХА СМБ Арматурное хозяйство), с доставкой, без установки. Эскалация в фев.2023 по CAPMAS "round steel", окт.2019=11450 EGP/т, фев.2023=28370,5 EGP/т | Q20: =IFERROR(INDEX([2]Лист1!$I:$I,AH20),"") -> т | R20: =IFERROR(INDEX([2]Лист1!$V:$V,AH20),"") -> 44599.913 | S20: =IFERROR(INDEX([2]Лист1!$L:$L,AH20),"") -> 43758 | T20: =IFERROR(INDEX([2]Лист1!$J:$J,AH20),"") -> Arcons Egypt | U20: =IFERROR(INDEX([2]Лист1!$K:$K,AH20),"") -> ТКП Arcons Egypt 20.10.2019 Эскалация в фев.2023 по CAPMAS "round steel", окт.2019=11450 EGP/т, фев.2023=28370,5 EGP/т | V20: =IFERROR(INDEX([2]Лист1!$E:$E,AI20),"") -> Усредненная цена готовых металлоконструкций (на примере здания ЦЕХА СМБ Арматурное хозяйство), с доставкой, без установки. Эскалация в фев.2023 по CAPMAS "round steel", окт.2019=11450 EGP/т, фев.2023=28370,5 EGP/т | W20: =IFERROR(INDEX([2]Лист1!$I:$I,AI20),"") -> т | X20: =IFERROR(INDEX([2]Лист1!$V:$V,AI20),"") -> 54511.004 | Y20: =IFERROR(INDEX([2]Лист1!$L:$L,AI20),"") -> 43762 | Z20: =IFERROR(INDEX([2]Лист1!$J:$J,AI20),"") -> Steelcom | AA20: =IFERROR(INDEX([2]Лист1!$K:$K,AI20),"") -> ТКП Steelcom 24.10.2019Эскалация в фев.2023 по CAPMAS "round steel", окт.2019=11450 EGP/т, фев.2023=28370,5 EGP/т | AB20: =IFERROR(INDEX([2]Лист1!$E:$E,AJ20),"") | AC20: =IFERROR(INDEX([2]Лист1!$I:$I,AJ20),"") | AD20: =IFERROR(INDEX([2]Лист1!$V:$V,AJ20),"") | AE20: =IFERROR(INDEX([2]Лист1!$L:$L,AJ20),"") | AF20: =IFERROR(INDEX([2]Лист1!$J:$J,AJ20),"") | AG20: =IFERROR(INDEX([2]Лист1!$K:$K,AJ20),"") | AH20: =MATCH(L20,[2]Лист1!$A:$A,0) -> 6656 | AI20: =MATCH(M20,[2]Лист1!$A:$A,0) -> 6657 | AJ20: =MATCH(N20,[2]Лист1!$A:$A,0) -> #N/A
A21: 1 | B21: ЛСР-03-05-206ТМ | C21: 3 | E21: ТЦ_23.7.01.02_31_3123315768_20.05.2022_02/КА п.76/ООО "Белэнергомаш-БЗЭМ" №006-00073 | F21: Трубопроводы низкого давления из углеродистой стали, 4 класса безопасности, Ду > 80мм_DN250,DN200, DN150, DN125, DN100, DN80 | G21: т | H21: 6.602 | I21: 211499.32 | J21: =H21*I21 -> 1396318.5 | K21: =J21/SUM($J$2:$J$1590) -> 0.010934589 | L21: =IFERROR(INDEX([1]мтр!G:G,MATCH($F21,[1]мтр!$C:$C,0)),"") -> 4859 | M21: =IFERROR(INDEX([1]мтр!H:H,MATCH($F21,[1]мтр!$C:$C,0)),"") -> 0 | N21: =IFERROR(INDEX([1]мтр!I:I,MATCH($F21,[1]мтр!$C:$C,0)),"") -> 0 | O21: =IFERROR(AVERAGE(R21,X21,AD21),"") -> 479788.26 | P21: =IFERROR(INDEX([2]Лист1!$E:$E,AH21),"") -> Трубопроводы низкого давления из углеродистой стали зданий UJA, UKD. Объём: 4526466 руб. / 2939,52 кг = 1540 RUB/кг. Транспорт 5800 USD (Договор ЕОС-закупки №629007, №7720/220816 от 07.09.2022, АСЭ_Рускон) /40DV контейнер 25 т, класс груза - 2, загрузка 85%. | Q21: =IFERROR(INDEX([2]Лист1!$I:$I,AH21),"") -> т | R21: =IFERROR(INDEX([2]Лист1!$V:$V,AH21),"") -> 479788.26 | S21: =IFERROR(INDEX([2]Лист1!$L:$L,AH21),"") -> 44753 | T21: =IFERROR(INDEX([2]Лист1!$J:$J,AH21),"") -> Белэнергомаш-БЗЭМ | U21: =IFERROR(INDEX([2]Лист1!$K:$K,AH21),"") -> Поставка трубопроводов по лоту 19677-248 Куд3;4. НМЦ от 11.07.2022, рассчитанная на основании п.1 раздела 3 главы 3 (приложения №8 к ЕОСЗ). | V21: =IFERROR(INDEX([2]Лист1!$E:$E,AI21),"") | W21: =IFERROR(INDEX([2]Лист1!$I:$I,AI21),"") | X21: =IFERROR(INDEX([2]Лист1!$V:$V,AI21),"") | Y21: =IFERROR(INDEX([2]Лист1!$L:$L,AI21),"") | Z21: =IFERROR(INDEX([2]Лист1!$J:$J,AI21),"") | AA21: =IFERROR(INDEX([2]Лист1!$K:$K,AI21),"") | AB21: =IFERROR(INDEX([2]Лист1!$E:$E,AJ21),"") | AC21: =IFERROR(INDEX([2]Лист1!$I:$I,AJ21),"") | AD21: =IFERROR(INDEX([2]Лист1!$V:$V,AJ21),"") | AE21: =IFERROR(INDEX([2]Лист1!$L:$L,AJ21),"") | AF21: =IFERROR(INDEX([2]Лист1!$J:$J,AJ21),"") | AG21: =IFERROR(INDEX([2]Лист1!$K:$K,AJ21),"") | AH21: =MATCH(L21,[2]Лист1!$A:$A,0) -> 4796 | AI21: =MATCH(M21,[2]Лист1!$A:$A,0) -> #N/A | AJ21: =MATCH(N21,[2]Лист1!$A:$A,0) -> #N/A
A22: 1 | B22: ЛСР-03-05-701АК | C22: 3 | E22: ТЦ_20.5.02.02_77_7702341124_01.06.2022_02 | F22: Коробка коммутации электропривода TB/ED-SS-30/32-2*EC2. Weidmuller 32 клемм 4H/N; III; QNC; | G22: шт. | H22: 76 | I22: 17239.58 | J22: =H22*I22 -> 1310208.1 | K22: =J22/SUM($J$2:$J$1590) -> 0.010260257 | L22: =IFERROR(INDEX([1]мтр!G:G,MATCH($F22,[1]мтр!$C:$C,0)),"") -> 5050 | M22: =IFERROR(INDEX([1]мтр!H:H,MATCH($F22,[1]мтр!$C:$C,0)),"") -> 0 | N22: =IFERROR(INDEX([1]мтр!I:I,MATCH($F22,[1]мтр!$C:$C,0)),"") -> 0 | O22: =IFERROR(AVERAGE(R22,X22,AD22),"") -> 37798.356 | P22: =IFERROR(INDEX([2]Лист1!$E:$E,AH22),"") -> Коробка Klippon TB/ED-SS-30/32-2*EC2. Транспорт экcпертно 5% | Q22: =IFERROR(INDEX([2]Лист1!$I:$I,AH22),"") -> шт. | R22: =IFERROR(INDEX([2]Лист1!$V:$V,AH22),"") -> 37798.356 | S22: =IFERROR(INDEX([2]Лист1!$L:$L,AH22),"") -> 44441 | T22: =IFERROR(INDEX([2]Лист1!$J:$J,AH22),"") -> Weidmuller | U22: =IFERROR(INDEX([2]Лист1!$K:$K,AH22),"") -> Письмо от А. Стрельцова, рук. "Атомное направление" | V22: =IFERROR(INDEX([2]Лист1!$E:$E,AI22),"") | W22: =IFERROR(INDEX([2]Лист1!$I:$I,AI22),"") | X22: =IFERROR(INDEX([2]Лист1!$V:$V,AI22),"") | Y22: =IFERROR(INDEX([2]Лист1!$L:$L,AI22),"") | Z22: =IFERROR(INDEX([2]Лист1!$J:$J,AI22),"") | AA22: =IFERROR(INDEX([2]Лист1!$K:$K,AI22),"") | AB22: =IFERROR(INDEX([2]Лист1!$E:$E,AJ22),"") | AC22: =IFERROR(INDEX([2]Лист1!$I:$I,AJ22),"") | AD22: =IFERROR(INDEX([2]Лист1!$V:$V,AJ22),"") | AE22: =IFERROR(INDEX([2]Лист1!$L:$L,AJ22),"") | AF22: =IFERROR(INDEX([2]Лист1!$J:$J,AJ22),"") | AG22: =IFERROR(INDEX([2]Лист1!$K:$K,AJ22),"") | AH22: =MATCH(L22,[2]Лист1!$A:$A,0) -> 2841 | AI22: =MATCH(M22,[2]Лист1!$A:$A,0) -> #N/A | AJ22: =MATCH(N22,[2]Лист1!$A:$A,0) -> #N/A
A23: 2 | B23: ЛСР-03-08-102С | C23: 3 | E23: 07.4.01.04-0002 | F23: Каркасы башен водонапорных решетчатых, прожекторные и молниезащиты, каркасы вентиляционных дымовых труб, опоры канатных дорог, высота до 200 м, масса 1 м от 50 до 100 кг_наружная обечайка | G23: т | H23: 91.9625 | I23: 13514.45 | J23: =H23*I23 -> 1242822.6 | K23: =J23/SUM($J$2:$J$1590) -> 0.0097325605 | L23: =IFERROR(INDEX([1]мтр!G:G,MATCH($F23,[1]мтр!$C:$C,0)),"") -> 7590 | M23: =IFERROR(INDEX([1]мтр!H:H,MATCH($F23,[1]мтр!$C:$C,0)),"") -> 7591 | N23: =IFERROR(INDEX([1]мтр!I:I,MATCH($F23,[1]мтр!$C:$C,0)),"") -> 0 | O23: =IFERROR(AVERAGE(R23,X23,AD23),"") -> 49555.459 | P23: =IFERROR(INDEX([2]Лист1!$E:$E,AH23),"") -> Усредненная цена готовых металлоконструкций (на примере здания ЦЕХА СМБ Арматурное хозяйство), с доставкой, без установки. Эскалация в фев.2023 по CAPMAS "round steel", окт.2019=11450 EGP/т, фев.2023=28370,5 EGP/т | Q23: =IFERROR(INDEX([2]Лист1!$I:$I,AH23),"") -> т | R23: =IFERROR(INDEX([2]Лист1!$V:$V,AH23),"") -> 44599.913 | S23: =IFERROR(INDEX([2]Лист1!$L:$L,AH23),"") -> 43758 | T23: =IFERROR(INDEX([2]Лист1!$J:$J,AH23),"") -> Arcons Egypt | U23: =IFERROR(INDEX([2]Лист1!$K:$K,AH23),"") -> ТКП Arcons Egypt 20.10.2019 Эскалация в фев.2023 по CAPMAS "round steel", окт.2019=11450 EGP/т, фев.2023=28370,5 EGP/т | V23: =IFERROR(INDEX([2]Лист1!$E:$E,AI23),"") -> Усредненная цена готовых металлоконструкций (на примере здания ЦЕХА СМБ Арматурное хозяйство), с доставкой, без установки. Эскалация в фев.2023 по CAPMAS "round steel", окт.2019=11450 EGP/т, фев.2023=28370,5 EGP/т | W23: =IFERROR(INDEX([2]Лист1!$I:$I,AI23),"") -> т | X23: =IFERROR(INDEX([2]Лист1!$V:$V,AI23),"") -> 54511.004 | Y23: =IFERROR(INDEX([2]Лист1!$L:$L,AI23),"") -> 43762 | Z23: =IFERROR(INDEX([2]Лист1!$J:$J,AI23),"") -> Steelcom | AA23: =IFERROR(INDEX([2]Лист1!$K:$K,AI23),"") -> ТКП Steelcom 24.10.2019Эскалация в фев.2023 по CAPMAS "round steel", окт.2019=11450 EGP/т, фев.2023=28370,5 EGP/т | AB23: =IFERROR(INDEX([2]Лист1!$E:$E,AJ23),"") | AC23: =IFERROR(INDEX([2]Лист1!$I:$I,AJ23),"") | AD23: =IFERROR(INDEX([2]Лист1!$V:$V,AJ23),"") | AE23: =IFERROR(INDEX([2]Лист1!$L:$L,AJ23),"") | AF23: =IFERROR(INDEX([2]Лист1!$J:$J,AJ23),"") | AG23: =IFERROR(INDEX([2]Лист1!$K:$K,AJ23),"") | AH23: =MATCH(L23,[2]Лист1!$A:$A,0) -> 6656 | AI23: =MATCH(M23,[2]Лист1!$A:$A,0) -> 6657 | AJ23: =MATCH(N23,[2]Лист1!$A:$A,0) -> #N/A
A24: 1 | B24: ЛСР-03-05-701АК | C24: 3 | E24: ТЦ_01.7.15.01_50_7710050305_31.05.2022_02 | F24: Анкер-шпилька HSA-R M12х145 Нж | G24: шт. | H24: 8736 | I24: 141.09 | J24: =H24*I24 -> 1232562.2 | K24: =J24/SUM($J$2:$J$1590) -> 0.0096522115 | L24: 7302 | M24: =IFERROR(INDEX([1]мтр!H:H,MATCH($F24,[1]мтр!$C:$C,0)),"") -> 0 | N24: =IFERROR(INDEX([1]мтр!I:I,MATCH($F24,[1]мтр!$C:$C,0)),"") -> 0 | O24: =IFERROR(AVERAGE(R24,X24,AD24),"") -> 316.58888 | P24: =IFERROR(INDEX([2]Лист1!$E:$E,AH24),"") -> Анкер-шпилька HSA-R M12x145 65/50/15. Транспорт экспертно 5% | Q24: =IFERROR(INDEX([2]Лист1!$I:$I,AH24),"") -> шт. | R24: =IFERROR(INDEX([2]Лист1!$V:$V,AH24),"") -> 316.58888 | S24: =IFERROR(INDEX([2]Лист1!$L:$L,AH24),"") -> 45087 | T24: =IFERROR(INDEX([2]Лист1!$J:$J,AH24),"") -> HILTI | U24: =IFERROR(INDEX([2]Лист1!$K:$K,AH24),"") -> https://www.hilti.it/c/CLS_FASTENER_7135/CLS_MECHANICAL_ANCHORS_7135/r5234?CHA_GLOBAL_ANC_SIZE=M12&CHD_ANCHOR_LENGTH=145%20mm&combo_content=750bc77ac94e3b3855a251dfb32ed670&salespackquantity=25%20pezzi&itemCode=2004210 | V24: =IFERROR(INDEX([2]Лист1!$E:$E,AI24),"") | W24: =IFERROR(INDEX([2]Лист1!$I:$I,AI24),"") | X24: =IFERROR(INDEX([2]Лист1!$V:$V,AI24),"") | Y24: =IFERROR(INDEX([2]Лист1!$L:$L,AI24),"") | Z24: =IFERROR(INDEX([2]Лист1!$J:$J,AI24),"") | AA24: =IFERROR(INDEX([2]Лист1!$K:$K,AI24),"") | AB24: =IFERROR(INDEX([2]Лист1!$E:$E,AJ24),"") | AC24: =IFERROR(INDEX([2]Лист1!$I:$I,AJ24),"") | AD24: =IFERROR(INDEX([2]Лист1!$V:$V,AJ24),"") | AE24: =IFERROR(INDEX([2]Лист1!$L:$L,AJ24),"") | AF24: =IFERROR(INDEX([2]Лист1!$J:$J,AJ24),"") | AG24: =IFERROR(INDEX([2]Лист1!$K:$K,AJ24),"") | AH24: =MATCH(L24,[2]Лист1!$A:$A,0) -> 6368 | AI24: =MATCH(M24,[2]Лист1!$A:$A,0) -> #N/A | AJ24: =MATCH(N24,[2]Лист1!$A:$A,0) -> #N/A
A25: 1 | B25: ЛСР-03-05-203ТМ | C25: 3 | E25: ТЦ_18.2.08.00_50_5503095632_05.07.2022_02 / КА п.25/ ЗАО "Сибгазстройдеталь" №897 | F25: Фильтр механический По типу ФС 125 С 16-0.4У DN 125; pmax=1.10 MPag; tmax=40 °С; Раб. среда: Вода химически обессоленная; Q=307.8 м?/ч; H-высота = 280 мм; L-длина = 400 мм; W-ширина = 199 мм; Кл 4Н_ФС125/16П-200-Ф1-Д1-УХЛ 1 ФС- фильтр сливной 125-номинальный диаметр, DN 16-давление 16 кг/см2 или (1,6Мпа) | G25: шт. | H25: 3 | I25: 392457.51 | J25: =H25*I25 -> 1177372.5 | K25: =J25/SUM($J$2:$J$1590) -> 0.0092200201 | L25: =IFERROR(INDEX([1]мтр!G:G,MATCH($F25,[1]мтр!$C:$C,0)),"") | M25: =IFERROR(INDEX([1]мтр!H:H,MATCH($F25,[1]мтр!$C:$C,0)),"") | N25: =IFERROR(INDEX([1]мтр!I:I,MATCH($F25,[1]мтр!$C:$C,0)),"") | O25: =IFERROR(AVERAGE(R25,X25,AD25),"") | P25: =IFERROR(INDEX([2]Лист1!$E:$E,AH25),"") | Q25: =IFERROR(INDEX([2]Лист1!$I:$I,AH25),"") | R25: =IFERROR(INDEX([2]Лист1!$V:$V,AH25),"") | S25: =IFERROR(INDEX([2]Лист1!$L:$L,AH25),"") | T25: =IFERROR(INDEX([2]Лист1!$J:$J,AH25),"") | U25: =IFERROR(INDEX([2]Лист1!$K:$K,AH25),"") | V25: =IFERROR(INDEX([2]Лист1!$E:$E,AI25),"") | W25: =IFERROR(INDEX([2]Лист1!$I:$I,AI25),"") | X25: =IFERROR(INDEX([2]Лист1!$V:$V,AI25),"") | Y25: =IFERROR(INDEX([2]Лист1!$L:$L,AI25),"") | Z25: =IFERROR(INDEX([2]Лист1!$J:$J,AI25),"") | AA25: =IFERROR(INDEX([2]Лист1!$K:$K,AI25),"") | AB25: =IFERROR(INDEX([2]Лист1!$E:$E,AJ25),"") | AC25: =IFERROR(INDEX([2]Лист1!$I:$I,AJ25),"") | AD25: =IFERROR(INDEX([2]Лист1!$V:$V,AJ25),"") | AE25: =IFERROR(INDEX([2]Лист1!$L:$L,AJ25),"") | AF25: =IFERROR(INDEX([2]Лист1!$J:$J,AJ25),"") | AG25: =IFERROR(INDEX([2]Лист1!$K:$K,AJ25),"") | AH25: =MATCH(L25,[2]Лист1!$A:$A,0) -> #N/A | AI25: =MATCH(M25,[2]Лист1!$A:$A,0) -> #N/A | AJ25: =MATCH(N25,[2]Лист1!$A:$A,0) -> #N/A
A26: 1 | B26: ЛСР-03-05-602Э | C26: 3 | E26: 21.1.08.03-0035 | F26: Кабель контрольный КВВГнг-FRLS 19х1,5 | G26: 1000 м | H26: 15.3 | I26: 69118.72 | J26: =H26*I26 -> 1057516.4 | K26: =J26/SUM($J$2:$J$1590) -> 0.0082814253 | L26: 7308 | M26: =IFERROR(INDEX([1]мтр!H:H,MATCH($F26,[1]мтр!$C:$C,0)),"") -> 0 | N26: =IFERROR(INDEX([1]мтр!I:I,MATCH($F26,[1]мтр!$C:$C,0)),"") -> 0 | O26: =IFERROR(AVERAGE(R26,X26,AD26),"") -> 198712.94 | P26: =IFERROR(INDEX([2]Лист1!$E:$E,AH26),"") -> Импорт из РФ_КВВГнг(А)-FRLS 19х1,5 660В ТУ 16.К19-11-2000 (ГОСТ 26411-85), Транспорт экспертно 5% | Q26: =IFERROR(INDEX([2]Лист1!$I:$I,AH26),"") -> 1000 м | R26: =IFERROR(INDEX([2]Лист1!$V:$V,AH26),"") -> 198712.94 | S26: =IFERROR(INDEX([2]Лист1!$L:$L,AH26),"") -> 45047 | T26: =IFERROR(INDEX([2]Лист1!$J:$J,AH26),"") -> Группа компаний "Электрокабель" | U26: =IFERROR(INDEX([2]Лист1!$K:$K,AH26),"") -> Прайс лист от 01.05.2023 группы компаний "Электрокабель" https://elektrokable.ru/Prais_kabel/Prais-list_kabel.xls | V26: =IFERROR(INDEX([2]Лист1!$E:$E,AI26),"") | W26: =IFERROR(INDEX([2]Лист1!$I:$I,AI26),"") | X26: =IFERROR(INDEX([2]Лист1!$V:$V,AI26),"") | Y26: =IFERROR(INDEX([2]Лист1!$L:$L,AI26),"") | Z26: =IFERROR(INDEX([2]Лист1!$J:$J,AI26),"") | AA26: =IFERROR(INDEX([2]Лист1!$K:$K,AI26),"") | AB26: =IFERROR(INDEX([2]Лист1!$E:$E,AJ26),"") | AC26: =IFERROR(INDEX([2]Лист1!$I:$I,AJ26),"") | AD26: =IFERROR(INDEX([2]Лист1!$V:$V,AJ26),"") | AE26: =IFERROR(INDEX([2]Лист1!$L:$L,AJ26),"") | AF26: =IFERROR(INDEX([2]Лист1!$J:$J,AJ26),"") | AG26: =IFERROR(INDEX([2]Лист1!$K:$K,AJ26),"") | AH26: =MATCH(L26,[2]Лист1!$A:$A,0) -> 6374 | AI26: =MATCH(M26,[2]Лист1!$A:$A,0) -> #N/A | AJ26: =MATCH(N26,[2]Лист1!$A:$A,0) -> #N/A
A27: 1 | B27: ЛСР-03-05-202ТМ | C27: 3 | E27: ТЦ_18.1.06.04_76_7610060282_05.05.22_02 / КА п.11 / ООО "Актан" № 955 | F27: Клапан запорный ручной (по типу А.КШ.Р.015.25.02.01), DN 15; Pmax= 0.6 Mpag; tmax= 35°C; Раб. среда: Обессоленная вода; Способ управления: Ручной привод; Тип присоединения: Фланцевый, Класс безопасности 4Н; материал - нж; с комплектом ответных фланцев под приварку с прокладками и крепежом_Кран шаровой А.КШ.Р.015.25.02.01 | G27: шт. | H27: 54 | I27: 19376.11 | J27: =H27*I27 -> 1046309.9 | K27: =J27/SUM($J$2:$J$1590) -> 0.0081936672 | L27: =IFERROR(INDEX([1]мтр!G:G,MATCH($F27,[1]мтр!$C:$C,0)),"") | M27: =IFERROR(INDEX([1]мтр!H:H,MATCH($F27,[1]мтр!$C:$C,0)),"") | N27: =IFERROR(INDEX([1]мтр!I:I,MATCH($F27,[1]мтр!$C:$C,0)),"") | O27: =IFERROR(AVERAGE(R27,X27,AD27),"") | P27: =IFERROR(INDEX([2]Лист1!$E:$E,AH27),"") | Q27: =IFERROR(INDEX([2]Лист1!$I:$I,AH27),"") | R27: =IFERROR(INDEX([2]Лист1!$V:$V,AH27),"") | S27: =IFERROR(INDEX([2]Лист1!$L:$L,AH27),"") | T27: =IFERROR(INDEX([2]Лист1!$J:$J,AH27),"") | U27: =IFERROR(INDEX([2]Лист1!$K:$K,AH27),"") | V27: =IFERROR(INDEX([2]Лист1!$E:$E,AI27),"") | W27: =IFERROR(INDEX([2]Лист1!$I:$I,AI27),"") | X27: =IFERROR(INDEX([2]Лист1!$V:$V,AI27),"") | Y27: =IFERROR(INDEX([2]Лист1!$L:$L,AI27),"") | Z27: =IFERROR(INDEX([2]Лист1!$J:$J,AI27),"") | AA27: =IFERROR(INDEX([2]Лист1!$K:$K,AI27),"") | AB27: =IFERROR(INDEX([2]Лист1!$E:$E,AJ27),"") | AC27: =IFERROR(INDEX([2]Лист1!$I:$I,AJ27),"") | AD27: =IFERROR(INDEX([2]Лист1!$V:$V,AJ27),"") | AE27: =IFERROR(INDEX([2]Лист1!$L:$L,AJ27),"") | AF27: =IFERROR(INDEX([2]Лист1!$J:$J,AJ27),"") | AG27: =IFERROR(INDEX([2]Лист1!$K:$K,AJ27),"") | AH27: =MATCH(L27,[2]Лист1!$A:$A,0) -> #N/A | AI27: =MATCH(M27,[2]Лист1!$A:$A,0) -> #N/A | AJ27: =MATCH(N27,[2]Лист1!$A:$A,0) -> #N/A
A28: 1 | B28: ЛСР-03-05-601СВ | C28: 3 | E28: ТЦ_20.2.07.00_31.03.2022_01/КА п.2/WIBE Group в России | F28: Кабельный лоток неперфорированный горячеоцинкованный, прямой, 100х100, длиной 2000 мм, с разделительной перегородкой и крышкой, включая монтажные элементы | G28: кг | H28: 2473.62 | I28: 398.56 | J28: =H28*I28 -> 985885.99 | K28: =J28/SUM($J$2:$J$1590) -> 0.0077204864 | L28: =IFERROR(INDEX([1]мтр!G:G,MATCH($F28,[1]мтр!$C:$C,0)),"") -> 5721 | M28: =IFERROR(INDEX([1]мтр!H:H,MATCH($F28,[1]мтр!$C:$C,0)),"") -> 0 | N28: =IFERROR(INDEX([1]мтр!I:I,MATCH($F28,[1]мтр!$C:$C,0)),"") -> 0 | O28: =IFERROR(AVERAGE(R28,X28,AD28),"") -> 359.93461 | P28: =IFERROR(INDEX([2]Лист1!$E:$E,AH28),"") -> Лоток листовой неперфорированный 100х100 L3000 сталь 0.7мм DKC 35101HDZ Транспорт экспертно 5% | Q28: =IFERROR(INDEX([2]Лист1!$I:$I,AH28),"") -> кг | R28: =IFERROR(INDEX([2]Лист1!$V:$V,AH28),"") -> 359.93461 | S28: =IFERROR(INDEX([2]Лист1!$L:$L,AH28),"") -> 44889 | T28: =IFERROR(INDEX([2]Лист1!$J:$J,AH28),"") -> N/A | U28: =IFERROR(INDEX([2]Лист1!$K:$K,AH28),"") -> https://rs24.ru/product/138276 (весовое значение: https://www.dkc.ru/ru/catalog/192/35101/) | V28: =IFERROR(INDEX([2]Лист1!$E:$E,AI28),"") | W28: =IFERROR(INDEX([2]Лист1!$I:$I,AI28),"") | X28: =IFERROR(INDEX([2]Лист1!$V:$V,AI28),"") | Y28: =IFERROR(INDEX([2]Лист1!$L:$L,AI28),"") | Z28: =IFERROR(INDEX([2]Лист1!$J:$J,AI28),"") | AA28: =IFERROR(INDEX([2]Лист1!$K:$K,AI28),"") | AB28: =IFERROR(INDEX([2]Лист1!$E:$E,AJ28),"") | AC28: =IFERROR(INDEX([2]Лист1!$I:$I,AJ28),"") | AD28: =IFERROR(INDEX([2]Лист1!$V:$V,AJ28),"") | AE28: =IFERROR(INDEX([2]Лист1!$L:$L,AJ28),"") | AF28: =IFERROR(INDEX([2]Лист1!$J:$J,AJ28),"") | AG28: =IFERROR(INDEX([2]Лист1!$K:$K,AJ28),"") | AH28: =MATCH(L28,[2]Лист1!$A:$A,0) -> 4943 | AI28: =MATCH(M28,[2]Лист1!$A:$A,0) -> #N/A | AJ28: =MATCH(N28,[2]Лист1!$A:$A,0) -> #N/A
A29: 1 | B29: ЛСР-03-05-101C | C29: 3 | E29: 12.1.02.10-0131 | F29: ТПО-мембрана гидроизоляционная, марка Sikaplan "WT 1200-20C" ("Sarnafil TG68-20") | G29: м2 | H29: 1797.12 | I29: 548.11 | J29: =H29*I29 -> 985019.44 | K29: =J29/SUM($J$2:$J$1590) -> 0.0077137005 | L29: =IFERROR(INDEX([1]мтр!G:G,MATCH($F29,[1]мтр!$C:$C,0)),"") -> 4683 | M29: =IFERROR(INDEX([1]мтр!H:H,MATCH($F29,[1]мтр!$C:$C,0)),"") -> 0 | N29: =IFERROR(INDEX([1]мтр!I:I,MATCH($F29,[1]мтр!$C:$C,0)),"") -> 0 | O29: =IFERROR(AVERAGE(R29,X29,AD29),"") -> 600 | P29: =IFERROR(INDEX([2]Лист1!$E:$E,AH29),"") -> ТПО-мембрана гидроизоляционная, марка Sikaplan WT 1200-20C | Q29: =IFERROR(INDEX([2]Лист1!$I:$I,AH29),"") -> м2 | R29: =IFERROR(INDEX([2]Лист1!$V:$V,AH29),"") -> 600 | S29: =IFERROR(INDEX([2]Лист1!$L:$L,AH29),"") -> 44608 | T29: =IFERROR(INDEX([2]Лист1!$J:$J,AH29),"") -> Sika Egypt For Construction Chemicals | U29: =IFERROR(INDEX([2]Лист1!$K:$K,AH29),"") -> Предложение SikaEgypt от 16.02.2022 | V29: =IFERROR(INDEX([2]Лист1!$E:$E,AI29),"") | W29: =IFERROR(INDEX([2]Лист1!$I:$I,AI29),"") | X29: =IFERROR(INDEX([2]Лист1!$V:$V,AI29),"") | Y29: =IFERROR(INDEX([2]Лист1!$L:$L,AI29),"") | Z29: =IFERROR(INDEX([2]Лист1!$J:$J,AI29),"") | AA29: =IFERROR(INDEX([2]Лист1!$K:$K,AI29),"") | AB29: =IFERROR(INDEX([2]Лист1!$E:$E,AJ29),"") | AC29: =IFERROR(INDEX([2]Лист1!$I:$I,AJ29),"") | AD29: =IFERROR(INDEX([2]Лист1!$V:$V,AJ29),"") | AE29: =IFERROR(INDEX([2]Лист1!$L:$L,AJ29),"") | AF29: =IFERROR(INDEX([2]Лист1!$J:$J,AJ29),"") | AG29: =IFERROR(INDEX([2]Лист1!$K:$K,AJ29),"") | AH29: =MATCH(L29,[2]Лист1!$A:$A,0) -> 3792 | AI29: =MATCH(M29,[2]Лист1!$A:$A,0) -> #N/A | AJ29: =MATCH(N29,[2]Лист1!$A:$A,0) -> #N/A
A30: 1 | B30: ЛСР-03-05-101C | C30: 3 | E30: 01.7.07.27-0013 | F30: Шпонка ТПО гидроизоляционная, наружного заложения для деформационных швов, марка "Sika Waterbar WT DF 400/30 MP" | G30: м | H30: 692.16 | I30: 1391.09 | J30: =H30*I30 -> 962856.85 | K30: =J30/SUM($J$2:$J$1590) -> 0.007540145 | L30: 3359 | M30: =IFERROR(INDEX([1]мтр!H:H,MATCH($F30,[1]мтр!$C:$C,0)),"") -> 0 | N30: =IFERROR(INDEX([1]мтр!I:I,MATCH($F30,[1]мтр!$C:$C,0)),"") -> 0 | O30: =IFERROR(AVERAGE(R30,X30,AD30),"") -> 684 | P30: =IFERROR(INDEX([2]Лист1!$E:$E,AH30),"") -> Шпонка Sika Waterbar WT AF 310/30. Транспорт от 50 тыс.EGP - бесплатно. | Q30: =IFERROR(INDEX([2]Лист1!$I:$I,AH30),"") -> м | R30: =IFERROR(INDEX([2]Лист1!$V:$V,AH30),"") -> 684 | S30: =IFERROR(INDEX([2]Лист1!$L:$L,AH30),"") -> 44320 | T30: =IFERROR(INDEX([2]Лист1!$J:$J,AH30),"") -> Sika Egypt For Construction Chemicals | U30: =IFERROR(INDEX([2]Лист1!$K:$K,AH30),"") -> Предложение SikaEgypt от 04.05.2021 | V30: =IFERROR(INDEX([2]Лист1!$E:$E,AI30),"") | W30: =IFERROR(INDEX([2]Лист1!$I:$I,AI30),"") | X30: =IFERROR(INDEX([2]Лист1!$V:$V,AI30),"") | Y30: =IFERROR(INDEX([2]Лист1!$L:$L,AI30),"") | Z30: =IFERROR(INDEX([2]Лист1!$J:$J,AI30),"") | AA30: =IFERROR(INDEX([2]Лист1!$K:$K,AI30),"") | AB30: =IFERROR(INDEX([2]Лист1!$E:$E,AJ30),"") | AC30: =IFERROR(INDEX([2]Лист1!$I:$I,AJ30),"") | AD30: =IFERROR(INDEX([2]Лист1!$V:$V,AJ30),"") | AE30: =IFERROR(INDEX([2]Лист1!$L:$L,AJ30),"") | AF30: =IFERROR(INDEX([2]Лист1!$J:$J,AJ30),"") | AG30: =IFERROR(INDEX([2]Лист1!$K:$K,AJ30),"") | AH30: =MATCH(L30,[2]Лист1!$A:$A,0) -> 4508 | AI30: =MATCH(M30,[2]Лист1!$A:$A,0) -> #N/A | AJ30: =MATCH(N30,[2]Лист1!$A:$A,0) -> #N/A
A31: 1 | B31: ЛСР-03-05-202ТМ | C31: 3 | E31: ТЦ_18.1.03.02_76_7610060282_05.05.22_02 / КА п.9 / ООО "Актан" № 955 | F31: Затвор дисковый поворотный (по типу А.КШ.Р.150.25.02.01), DN 150; Pmax=0.6MPag; Tmax=35 °С; Раб. среда: Обессоленная вода; Способ управления: Ручной привод; Тип присоединения: Фланцевый; Класс безопасности 4Н; материал - нж; с комплектом ответных фланцев под приварку с прокладками и крепежом_Кран шаровой А.КШ.Р.150.25.02.01 | G31: шт. | H31: 4 | I31: 229485.17 | J31: =H31*I31 -> 917940.68 | K31: =J31/SUM($J$2:$J$1590) -> 0.0071884058 | L31: =IFERROR(INDEX([1]мтр!G:G,MATCH($F31,[1]мтр!$C:$C,0)),"") | M31: =IFERROR(INDEX([1]мтр!H:H,MATCH($F31,[1]мтр!$C:$C,0)),"") | N31: =IFERROR(INDEX([1]мтр!I:I,MATCH($F31,[1]мтр!$C:$C,0)),"") | O31: =IFERROR(AVERAGE(R31,X31,AD31),"") | P31: =IFERROR(INDEX([2]Лист1!$E:$E,AH31),"") | Q31: =IFERROR(INDEX([2]Лист1!$I:$I,AH31),"") | R31: =IFERROR(INDEX([2]Лист1!$V:$V,AH31),"") | S31: =IFERROR(INDEX([2]Лист1!$L:$L,AH31),"") | T31: =IFERROR(INDEX([2]Лист1!$J:$J,AH31),"") | U31: =IFERROR(INDEX([2]Лист1!$K:$K,AH31),"") | V31: =IFERROR(INDEX([2]Лист1!$E:$E,AI31),"") | W31: =IFERROR(INDEX([2]Лист1!$I:$I,AI31),"") | X31: =IFERROR(INDEX([2]Лист1!$V:$V,AI31),"") | Y31: =IFERROR(INDEX([2]Лист1!$L:$L,AI31),"") | Z31: =IFERROR(INDEX([2]Лист1!$J:$J,AI31),"") | AA31: =IFERROR(INDEX([2]Лист1!$K:$K,AI31),"") | AB31: =IFERROR(INDEX([2]Лист1!$E:$E,AJ31),"") | AC31: =IFERROR(INDEX([2]Лист1!$I:$I,AJ31),"") | AD31: =IFERROR(INDEX([2]Лист1!$V:$V,AJ31),"") | AE31: =IFERROR(INDEX([2]Лист1!$L:$L,AJ31),"") | AF31: =IFERROR(INDEX([2]Лист1!$J:$J,AJ31),"") | AG31: =IFERROR(INDEX([2]Лист1!$K:$K,AJ31),"") | AH31: =MATCH(L31,[2]Лист1!$A:$A,0) -> #N/A | AI31: =MATCH(M31,[2]Лист1!$A:$A,0) -> #N/A | AJ31: =MATCH(N31,[2]Лист1!$A:$A,0) -> #N/A
A32: 1 | B32: ЛСР-03-05-203ТМ | C32: 3 | E32: ТЦ_18.1.06.00_50_5503095632_05.07.2022_02 /КА п.50/ ЗАО "Сибгазстройдеталь" №897 | F32: Запорная арматура По типу 2с-25-1Н DN 150; pmax=0.40 MPag; tmax=155 °С / °C; Раб. среда:Пар собственных нужд; Способ управления: Ручной привод; Тип присоединения: Под приварку Кл.4Н, угл.ст. | G32: шт. | H32: 6 | I32: 151166.68 | J32: =H32*I32 -> 907000.08 | K32: =J32/SUM($J$2:$J$1590) -> 0.0071027298 | L32: 7314 | M32: =IFERROR(INDEX([1]мтр!H:H,MATCH($F32,[1]мтр!$C:$C,0)),"") | N32: =IFERROR(INDEX([1]мтр!I:I,MATCH($F32,[1]мтр!$C:$C,0)),"") | O32: =IFERROR(AVERAGE(R32,X32,AD32),"") -> 0 | P32: =IFERROR(INDEX([2]Лист1!$E:$E,AH32),"") -> 0 | Q32: =IFERROR(INDEX([2]Лист1!$I:$I,AH32),"") -> 0 | R32: =IFERROR(INDEX([2]Лист1!$V:$V,AH32),"") -> 0 | S32: =IFERROR(INDEX([2]Лист1!$L:$L,AH32),"") -> 0 | T32: =IFERROR(INDEX([2]Лист1!$J:$J,AH32),"") -> 0 | U32: =IFERROR(INDEX([2]Лист1!$K:$K,AH32),"") -> 0 | V32: =IFERROR(INDEX([2]Лист1!$E:$E,AI32),"") | W32: =IFERROR(INDEX([2]Лист1!$I:$I,AI32),"") | X32: =IFERROR(INDEX([2]Лист1!$V:$V,AI32),"") | Y32: =IFERROR(INDEX([2]Лист1!$L:$L,AI32),"") | Z32: =IFERROR(INDEX([2]Лист1!$J:$J,AI32),"") | AA32: =IFERROR(INDEX([2]Лист1!$K:$K,AI32),"") | AB32: =IFERROR(INDEX([2]Лист1!$E:$E,AJ32),"") | AC32: =IFERROR(INDEX([2]Лист1!$I:$I,AJ32),"") | AD32: =IFERROR(INDEX([2]Лист1!$V:$V,AJ32),"") | AE32: =IFERROR(INDEX([2]Лист1!$L:$L,AJ32),"") | AF32: =IFERROR(INDEX([2]Лист1!$J:$J,AJ32),"") | AG32: =IFERROR(INDEX([2]Лист1!$K:$K,AJ32),"") | AH32: =MATCH(L32,[2]Лист1!$A:$A,0) -> 6380 | AI32: =MATCH(M32,[2]Лист1!$A:$A,0) -> #N/A | AJ32: =MATCH(N32,[2]Лист1!$A:$A,0) -> #N/A
